Workbook

Sheet Meters
A1: Д/д | B1: Марк | D1: Үйлдвэрлэгч | E1: Хаана хаана байгаа | F1: Тоо ширхэг | G1: Хэдэн онд авсан | H1: Хаанаас авсан | I1: Мэдээлэл | J1: Загвар | K1: Mark | L1: HES-тэй эсэх | M1: Төрөл | N1: Фаз | O1: Тоолуурын төрөл | P1: Стандарт | Q1: Мэдээлэл дамжуулалт | R1: Солих | S1: Цэций хороолол | T1: Уурхайчин хороолол
A2: 1 | B2: C2000 | D2: Microstar C2000 smart meter | F2: =COUNTIF(#REF!, Meters!B2) -> #REF! | J2: Microstar C2000 smart meter | M2: 1 фаз электрон | N2: 1 | O2: Ухаалаг тоолуур | P2: IEC 62053-21, IEC 62052-11, EN 50470 | Q2: 21
A3: 2 | B3: DDS286 | D3: Wanlong Electron Science technology | F3: =COUNTIF(#REF!, Meters!B3) -> #REF! | G3: 2012 | H3: Measurement | I3: 1 фаз | J3: DDS286 | M3: 1 фаз электрон
A4: 3 | B4: DDS26 | D4: Star Instrument | F4: =COUNTIF(#REF!, Meters!B4) -> #REF! | G4: 2012 | H4: ENT, Energy Technology Center | I4: 1 фаз | J4: DDS26 | M4: 1 фаз электрон
A5: 4 | B5: DDSF36A | F5: =COUNTIF(#REF!, Meters!B5) -> #REF! | J5: DDSF36A | M5: 1 фаз prepaid
A6: 5 | B6: DDS155 | F6: =COUNTIF(#REF!, Meters!B6) -> #REF! | J6: DDS155 | M6: 1 фаз электрон
A7: 6 | B7: DDSY283SR | D7: Holley | F7: =COUNTIF(#REF!, Meters!B7) -> #REF! | J7: DDSY283SR | M7: 1 фаз ухаалаг prepaid
A8: 7 | B8: DDS226 | F8: =COUNTIF(#REF!, Meters!B8) -> #REF! | J8: DDS226 | M8: 1 фаз электрон
A9: 8 | B9: LGG100 | F9: =COUNTIF(#REF!, Meters!B9) -> #REF! | J9: LGG100 | M9: 1 фаз
A10: 9 | B10: CHS160 | D10: CHINT / OEM | F10: =COUNTIF(#REF!, Meters!B10) -> #REF! | J10: CHS160 | M10: 1 фаз
A11: 10 | B11: DDS 26 | D11: Star Instrument | F11: =COUNTIF(#REF!, Meters!B11) -> #REF! | G11: 2012 | H11: ENT | J11: DDS26 | K11: DDS26 | L11: HES байхгүй | M11: 1 фаз электрон | N11: 1
A12: 11 | B12: DDS285 | F12: =COUNTIF(#REF!, Meters!B12) -> #REF! | J12: DDS285 | M12: 1 фаз
A13: 12 | B13: DDSD285 | F13: =COUNTIF(#REF!, Meters!B13) -> #REF! | J13: DDSD285 | M13: 1 фаз олон тарифтай
A14: 13 | B14: DТSD22 | F14: =COUNTIF(#REF!, Meters!B14) -> #REF! | J14: DTSD22 | M14: 3 фаз
A15: 14 | B15: A1140-RAL-S-4T | D15: Elster | F15: =COUNTIF(#REF!, Meters!B15) -> #REF! | G15: 2005 | H15: Эрчим Сүлжээ | I15: 1 фаз | J15: A1140-RAL-S-4T | M15: 3 фаз AMR
A16: 15 | B16: DTS27 | F16: =COUNTIF(#REF!, Meters!B16) -> #REF! | J16: DTS27 | M16: 3 фаз
A17: 16 | B17: DTSD545S | D17: Holley | F17: =COUNTIF(#REF!, Meters!B17) -> #REF! | J17: DTSD545S | M17: 3 фаз Smart Meter
A18: 17 | B18: DTS 27A | F18: =COUNTIF(#REF!, Meters!B18) -> #REF! | J18: DTS27A | M18: 3 фаз
A19: 18 | B19: A1840-RАL-S-4T | D19: Elster | F19: =COUNTIF(#REF!, Meters!B19) -> #REF! | J19: A1840-RAL-S-4T | M19: 3 фаз Smart
A20: 19 | B20: DTSD111 | F20: =COUNTIF(#REF!, Meters!B20) -> #REF! | J20: DTSD111 | M20: 3 фаз
A21: 20 | B21: хоосон | D21: Energomera | F21: =COUNTIF(#REF!, Meters!B21) -> #REF! | J21: ЦЭ6803ВМ | M21: 3 фаз
A22: 21 | B22: ЦЭ6803ВМ | F22: =COUNTIF(#REF!, Meters!B22) -> #REF!
A23: 22 | B23: DTS122 | F23: =COUNTIF(#REF!, Meters!B23) -> #REF! | J23: DTS122 | M23: 3 фаз
A24: 23 | B24: A1802RAL-P4G-DW-3 | F24: =COUNTIF(#REF!, Meters!B24) -> #REF! | J24: IES62053-21 DTS122 | M24: 3 фаз
A25: 24 | B25: IES62053-21DTS122 | D25: Elster | F25: =COUNTIF(#REF!, Meters!B25) -> #REF! | J25: A1802RAL-P4G-DW-3 | M25: 3 фаз Smart
A26: 25 | B26: DDS122 | F26: =COUNTIF(#REF!, Meters!B26) -> #REF! | J26: DDS122 | M26: 1 фаз
A27: 26 | B27: ЦЭ68038 | D27: Energomera | F27: =COUNTIF(#REF!, Meters!B27) -> #REF! | J27: ЦЭ68038 | M27: 3 фаз
A28: 27 | B28: A1140-10-RAL-BW-4T | D28: Elster | F28: =COUNTIF(#REF!, Meters!B28) -> #REF! | J28: A1140-10-RAL-BW-4T | M28: 3 фаз
A29: 28 | B29: А1140RAL-SW-4T | D29: Elster | F29: =COUNTIF(#REF!, Meters!B29) -> #REF! | J29: A1140RAL-SW-4T | M29: 3 фаз
A30: 29 | B30: A1805RL-P4G-DW-3 | D30: Elster | F30: =COUNTIF(#REF!, Meters!B30) -> #REF! | J30: A1805RL-P4G-DW-3 | M30: 3 фаз Smart
A31: 30 | B31: P2000-D | F31: =COUNTIF(#REF!, Meters!B31) -> #REF! | J31: P2000-D | M31: 1 фаз
A32: 31 | B32: А1140RAL-S-4T | F32: =COUNTIF(#REF!, Meters!B32) -> #REF!
A33: 32 | B33: CHS 330 | D33: CHINT / OEM | F33: =COUNTIF(#REF!, Meters!B33) -> #REF! | J33: CHS330 | M33: 3 фаз
A34: 33 | B34: DDSF217 | F34: =COUNTIF(#REF!, Meters!B34) -> #REF! | J34: DDSF217 | M34: 1 фаз prepaid
A35: 34 | B35: СЕ303 | D35: Energomera | F35: =COUNTIF(#REF!, Meters!B35) -> #REF! | J35: СЕ303 | M35: 3 фаз
A36: 35 | B36: P2000-T | F36: =COUNTIF(#REF!, Meters!B36) -> #REF! | J36: P2000-T | M36: 3 фаз
A37: 36 | B37: DTS27A | F37: =COUNTIF(#REF!, Meters!B37) -> #REF!
A38: 37 | B38: DDS22 | D38: Shenzhen Haoningda Meters | F38: =COUNTIF(#REF!, Meters!B38) -> #REF! | G38: 2013 | H38: Тодруулах | I38: 1 фаз | J38: DDS22 | M38: 1 фаз | P38: IEC62053-21
A39: 38 | B39: DTZY666-Z | F39: =COUNTIF(#REF!, Meters!B39) -> #REF! | J39: DTZY666-Z | M39: 3 фаз Smart
A40: 39 | B40: DDSF22 (60A) | F40: =COUNTIF(#REF!, Meters!B40) -> #REF! | J40: DDSF22 (60A) | M40: 1 фаз prepaid
...
